<?xml version="1.0"?>
<robot name="modified_3dof_arm">

  <!-- WORLD (dummy link for a floating base) -->
  <link name="world"/>
  
  <!-- BASE LINK with integrated yaw movement -->
  <link name="base_link">
    <visual>
      <origin xyz="0 0 0" rpy="0 0 0"/>
      <geometry>
        <cylinder length="0.05" radius="0.1"/>
      </geometry>
      <material name="grey">
        <color rgba="0.5 0.5 0.5 1.0"/>
      </material>
    </visual>
  </link>
  
  <!-- BASE YAW JOINT: allows yaw rotation of the base relative to the world -->
  <joint name="base_yaw_joint" type="revolute">
    <parent link="world"/>
    <child link="base_link"/>
    <origin xyz="0 0 0.025" rpy="0 0 0"/>
    <axis xyz="0 0 1"/>
    <limit lower="-1.57" upper="4.71" effort="100" velocity="1.0"/>
  </joint>
  
  <!-- FIXED JOINT: attaches shoulder_link directly to base_link -->
  <joint name="base_to_shoulder_fixed" type="revolute">
    <parent link="base_link"/>
    <child link="shoulder_link"/>
    <origin xyz="0 0 0" rpy="0 0 0"/>
    <axis xyz="1 0 0"/>
    <limit lower="-0.785" upper="0.873" effort="100" velocity="1.0"/>
  </joint>
  
  <!-- SHOULDER LINK (BLUE) -->
  <link name="shoulder_link">
    <visual>
      <origin xyz="0 0 0.1" rpy="0 0 0"/>
      <geometry>
        <cylinder length="0.2" radius="0.02"/>
      </geometry>
      <material name="blue">
        <color rgba="0.2 0.2 0.8 1.0"/>
      </material>
    </visual>
  </link>
  
  <!-- JOINT 2: SHOULDER (X-AXIS ROTATION) -->
  <joint name="shoulder_joint" type="revolute">
    <parent link="shoulder_link"/>
    <child link="elbow_link"/>
    <origin xyz="0 0 0.2" rpy="0 0 0"/>
    <axis xyz="1 0 0"/>
    <limit lower="-0.785" upper="2.356" effort="100" velocity="1.0"/>
  </joint>
  
  <!-- ELBOW LINK (PURPLE) -->
  <link name="elbow_link">
    <visual>
      <origin xyz="0 0 0.075" rpy="0 0 0"/>
      <geometry>
        <cylinder length="0.15" radius="0.015"/>
      </geometry>
      <material name="purple">
        <color rgba="0.5 0 0.5 1.0"/>
      </material>
    </visual>
  </link>

</robot>